{
 "cells": [
  {
   "cell_type": "code",
   "execution_count": 1,
   "id": "59c7a320",
   "metadata": {},
   "outputs": [
    {
     "name": "stderr",
     "output_type": "stream",
     "text": [
      "Using TensorFlow backend.\n"
     ]
    }
   ],
   "source": [
    "# import libraries\n",
    "import numpy as np\n",
    "import matplotlib.pyplot as plt\n",
    "from sklearn import svm, datasets\n",
    "from sklearn.svm import SVC\n",
    "from sklearn.model_selection import train_test_split\n",
    "from sklearn.utils import shuffle\n",
    "from sklearn.metrics import classification_report,accuracy_score\n",
    "import pandas as pd\n",
    "from sklearn.datasets import load_iris\n",
    "import numpy as np\n",
    "from sklearn.metrics import classification_report,accuracy_score\n",
    "from sklearn import svm\n",
    "import os\n",
    "import numpy as np\n",
    "from keras.preprocessing import image\n",
    "import cv2\n",
    "import dlib"
   ]
  },
  {
   "cell_type": "code",
   "execution_count": null,
   "id": "1de0b8bd",
   "metadata": {},
   "outputs": [
    {
     "name": "stdout",
     "output_type": "stream",
     "text": [
      "ERROR! Session/line number was not unique in database. History logging moved to new session 143\n"
     ]
    },
    {
     "name": "stderr",
     "output_type": "stream",
     "text": [
      "ERROR:root:Internal Python error in the inspect module.\n",
      "Below is the traceback from this internal error.\n",
      "\n",
      "ERROR:root:Internal Python error in the inspect module.\n",
      "Below is the traceback from this internal error.\n",
      "\n",
      "ERROR:root:Internal Python error in the inspect module.\n",
      "Below is the traceback from this internal error.\n",
      "\n"
     ]
    },
    {
     "name": "stdout",
     "output_type": "stream",
     "text": [
      "Traceback (most recent call last):\n",
      "  File \"D:\\Anaconda\\lib\\site-packages\\IPython\\core\\interactiveshell.py\", line 3444, in run_code\n",
      "    exec(code_obj, self.user_global_ns, self.user_ns)\n",
      "  File \"C:\\Users\\13542\\AppData\\Local\\Temp/ipykernel_18296/3045016949.py\", line 100, in <module>\n",
      "    tr_X, tr_Y, te_X, te_Y= get_data()\n",
      "  File \"C:\\Users\\13542\\AppData\\Local\\Temp/ipykernel_18296/3045016949.py\", line 57, in get_data\n",
      "    X,y = extract_features_labels()\n",
      "  File \"C:\\Users\\13542\\AppData\\Local\\Temp/ipykernel_18296/3045016949.py\", line 43, in extract_features_labels\n",
      "    img_read = cv2.imread(img)  # 把图片转化成 numpy.ndarray，shape=(512, 512, 3)\n",
      "cv2.error: OpenCV(3.4.2) C:\\Miniconda3\\conda-bld\\opencv-suite_1534379934306\\work\\modules\\core\\src\\alloc.cpp:55: error: (-4:Insufficient memory) Failed to allocate 786432 bytes in function 'cv::OutOfMemoryError'\n",
      "\n",
      "\n",
      "During handling of the above exception, another exception occurred:\n",
      "\n",
      "Traceback (most recent call last):\n",
      "  File \"D:\\Anaconda\\lib\\site-packages\\IPython\\core\\interactiveshell.py\", line 2064, in showtraceback\n",
      "    stb = value._render_traceback_()\n",
      "AttributeError: 'error' object has no attribute '_render_traceback_'\n",
      "\n",
      "During handling of the above exception, another exception occurred:\n",
      "\n",
      "Traceback (most recent call last):\n",
      "  File \"D:\\Anaconda\\lib\\site-packages\\IPython\\core\\ultratb.py\", line 1101, in get_records\n",
      "    return _fixed_getinnerframes(etb, number_of_lines_of_context, tb_offset)\n",
      "  File \"D:\\Anaconda\\lib\\site-packages\\IPython\\core\\ultratb.py\", line 248, in wrapped\n",
      "    return f(*args, **kwargs)\n",
      "  File \"D:\\Anaconda\\lib\\site-packages\\IPython\\core\\ultratb.py\", line 281, in _fixed_getinnerframes\n",
      "    records = fix_frame_records_filenames(inspect.getinnerframes(etb, context))\n",
      "  File \"D:\\Anaconda\\lib\\inspect.py\", line 1502, in getinnerframes\n",
      "    frameinfo = (tb.tb_frame,) + getframeinfo(tb, context)\n",
      "  File \"D:\\Anaconda\\lib\\inspect.py\", line 1460, in getframeinfo\n",
      "    filename = getsourcefile(frame) or getfile(frame)\n",
      "  File \"D:\\Anaconda\\lib\\inspect.py\", line 696, in getsourcefile\n",
      "    if getattr(getmodule(object, filename), '__loader__', None) is not None:\n",
      "  File \"D:\\Anaconda\\lib\\inspect.py\", line 733, in getmodule\n",
      "    if ismodule(module) and hasattr(module, '__file__'):\n",
      "  File \"D:\\Anaconda\\lib\\site-packages\\tensorflow\\__init__.py\", line 50, in __getattr__\n",
      "    module = self._load()\n",
      "  File \"D:\\Anaconda\\lib\\site-packages\\tensorflow\\__init__.py\", line 44, in _load\n",
      "    module = _importlib.import_module(self.__name__)\n",
      "  File \"D:\\Anaconda\\lib\\importlib\\__init__.py\", line 127, in import_module\n",
      "    return _bootstrap._gcd_import(name[level:], package, level)\n",
      "  File \"<frozen importlib._bootstrap>\", line 1006, in _gcd_import\n",
      "  File \"<frozen importlib._bootstrap>\", line 983, in _find_and_load\n",
      "  File \"<frozen importlib._bootstrap>\", line 965, in _find_and_load_unlocked\n",
      "ModuleNotFoundError: No module named 'tensorflow_core.estimator'\n",
      "Traceback (most recent call last):\n",
      "  File \"D:\\Anaconda\\lib\\site-packages\\IPython\\core\\interactiveshell.py\", line 3444, in run_code\n",
      "    exec(code_obj, self.user_global_ns, self.user_ns)\n",
      "  File \"C:\\Users\\13542\\AppData\\Local\\Temp/ipykernel_18296/3045016949.py\", line 100, in <module>\n",
      "    tr_X, tr_Y, te_X, te_Y= get_data()\n",
      "  File \"C:\\Users\\13542\\AppData\\Local\\Temp/ipykernel_18296/3045016949.py\", line 57, in get_data\n",
      "    X,y = extract_features_labels()\n",
      "  File \"C:\\Users\\13542\\AppData\\Local\\Temp/ipykernel_18296/3045016949.py\", line 43, in extract_features_labels\n",
      "    img_read = cv2.imread(img)  # 把图片转化成 numpy.ndarray，shape=(512, 512, 3)\n",
      "cv2.error: OpenCV(3.4.2) C:\\Miniconda3\\conda-bld\\opencv-suite_1534379934306\\work\\modules\\core\\src\\alloc.cpp:55: error: (-4:Insufficient memory) Failed to allocate 786432 bytes in function 'cv::OutOfMemoryError'\n",
      "\n",
      "\n",
      "During handling of the above exception, another exception occurred:\n",
      "\n",
      "Traceback (most recent call last):\n",
      "  File \"D:\\Anaconda\\lib\\site-packages\\IPython\\core\\interactiveshell.py\", line 2064, in showtraceback\n",
      "    stb = value._render_traceback_()\n",
      "AttributeError: 'error' object has no attribute '_render_traceback_'\n",
      "\n",
      "During handling of the above exception, another exception occurred:\n",
      "\n",
      "Traceback (most recent call last):\n",
      "  File \"D:\\Anaconda\\lib\\site-packages\\IPython\\core\\interactiveshell.py\", line 3364, in run_ast_nodes\n",
      "    if (await self.run_code(code, result,  async_=asy)):\n",
      "  File \"D:\\Anaconda\\lib\\site-packages\\IPython\\core\\interactiveshell.py\", line 3461, in run_code\n",
      "    self.showtraceback(running_compiled_code=True)\n",
      "  File \"D:\\Anaconda\\lib\\site-packages\\IPython\\core\\interactiveshell.py\", line 2067, in showtraceback\n",
      "    value, tb, tb_offset=tb_offset)\n",
      "  File \"D:\\Anaconda\\lib\\site-packages\\IPython\\core\\ultratb.py\", line 1368, in structured_traceback\n",
      "    self, etype, value, tb, tb_offset, number_of_lines_of_context)\n",
      "  File \"D:\\Anaconda\\lib\\site-packages\\IPython\\core\\ultratb.py\", line 1268, in structured_traceback\n",
      "    self, etype, value, tb, tb_offset, number_of_lines_of_context\n",
      "  File \"D:\\Anaconda\\lib\\site-packages\\IPython\\core\\ultratb.py\", line 1125, in structured_traceback\n",
      "    tb_offset)\n",
      "  File \"D:\\Anaconda\\lib\\site-packages\\IPython\\core\\ultratb.py\", line 1082, in format_exception_as_a_whole\n",
      "    last_unique, recursion_repeat = find_recursion(orig_etype, evalue, records)\n",
      "  File \"D:\\Anaconda\\lib\\site-packages\\IPython\\core\\ultratb.py\", line 382, in find_recursion\n",
      "    return len(records), 0\n",
      "TypeError: object of type 'NoneType' has no len()\n",
      "\n",
      "During handling of the above exception, another exception occurred:\n",
      "\n",
      "Traceback (most recent call last):\n",
      "  File \"D:\\Anaconda\\lib\\site-packages\\IPython\\core\\interactiveshell.py\", line 2064, in showtraceback\n",
      "    stb = value._render_traceback_()\n",
      "AttributeError: 'TypeError' object has no attribute '_render_traceback_'\n",
      "\n",
      "During handling of the above exception, another exception occurred:\n",
      "\n",
      "Traceback (most recent call last):\n",
      "  File \"D:\\Anaconda\\lib\\site-packages\\IPython\\core\\ultratb.py\", line 1101, in get_records\n",
      "    return _fixed_getinnerframes(etb, number_of_lines_of_context, tb_offset)\n",
      "  File \"D:\\Anaconda\\lib\\site-packages\\IPython\\core\\ultratb.py\", line 248, in wrapped\n",
      "    return f(*args, **kwargs)\n",
      "  File \"D:\\Anaconda\\lib\\site-packages\\IPython\\core\\ultratb.py\", line 281, in _fixed_getinnerframes\n",
      "    records = fix_frame_records_filenames(inspect.getinnerframes(etb, context))\n",
      "  File \"D:\\Anaconda\\lib\\inspect.py\", line 1502, in getinnerframes\n",
      "    frameinfo = (tb.tb_frame,) + getframeinfo(tb, context)\n",
      "  File \"D:\\Anaconda\\lib\\inspect.py\", line 1460, in getframeinfo\n",
      "    filename = getsourcefile(frame) or getfile(frame)\n",
      "  File \"D:\\Anaconda\\lib\\inspect.py\", line 696, in getsourcefile\n",
      "    if getattr(getmodule(object, filename), '__loader__', None) is not None:\n",
      "  File \"D:\\Anaconda\\lib\\inspect.py\", line 733, in getmodule\n",
      "    if ismodule(module) and hasattr(module, '__file__'):\n",
      "  File \"D:\\Anaconda\\lib\\site-packages\\tensorflow\\__init__.py\", line 50, in __getattr__\n",
      "    module = self._load()\n",
      "  File \"D:\\Anaconda\\lib\\site-packages\\tensorflow\\__init__.py\", line 44, in _load\n",
      "    module = _importlib.import_module(self.__name__)\n",
      "  File \"D:\\Anaconda\\lib\\importlib\\__init__.py\", line 127, in import_module\n",
      "    return _bootstrap._gcd_import(name[level:], package, level)\n",
      "  File \"<frozen importlib._bootstrap>\", line 1006, in _gcd_import\n",
      "  File \"<frozen importlib._bootstrap>\", line 983, in _find_and_load\n",
      "  File \"<frozen importlib._bootstrap>\", line 965, in _find_and_load_unlocked\n",
      "ModuleNotFoundError: No module named 'tensorflow_core.estimator'\n",
      "Traceback (most recent call last):\n",
      "  File \"D:\\Anaconda\\lib\\site-packages\\IPython\\core\\interactiveshell.py\", line 3444, in run_code\n",
      "    exec(code_obj, self.user_global_ns, self.user_ns)\n",
      "  File \"C:\\Users\\13542\\AppData\\Local\\Temp/ipykernel_18296/3045016949.py\", line 100, in <module>\n",
      "    tr_X, tr_Y, te_X, te_Y= get_data()\n",
      "  File \"C:\\Users\\13542\\AppData\\Local\\Temp/ipykernel_18296/3045016949.py\", line 57, in get_data\n",
      "    X,y = extract_features_labels()\n",
      "  File \"C:\\Users\\13542\\AppData\\Local\\Temp/ipykernel_18296/3045016949.py\", line 43, in extract_features_labels\n",
      "    img_read = cv2.imread(img)  # 把图片转化成 numpy.ndarray，shape=(512, 512, 3)\n",
      "cv2.error: OpenCV(3.4.2) C:\\Miniconda3\\conda-bld\\opencv-suite_1534379934306\\work\\modules\\core\\src\\alloc.cpp:55: error: (-4:Insufficient memory) Failed to allocate 786432 bytes in function 'cv::OutOfMemoryError'\n",
      "\n",
      "\n",
      "During handling of the above exception, another exception occurred:\n",
      "\n",
      "Traceback (most recent call last):\n",
      "  File \"D:\\Anaconda\\lib\\site-packages\\IPython\\core\\interactiveshell.py\", line 2064, in showtraceback\n",
      "    stb = value._render_traceback_()\n",
      "AttributeError: 'error' object has no attribute '_render_traceback_'\n",
      "\n",
      "During handling of the above exception, another exception occurred:\n",
      "\n",
      "Traceback (most recent call last):\n",
      "  File \"D:\\Anaconda\\lib\\site-packages\\IPython\\core\\interactiveshell.py\", line 3364, in run_ast_nodes\n",
      "    if (await self.run_code(code, result,  async_=asy)):\n",
      "  File \"D:\\Anaconda\\lib\\site-packages\\IPython\\core\\interactiveshell.py\", line 3461, in run_code\n",
      "    self.showtraceback(running_compiled_code=True)\n",
      "  File \"D:\\Anaconda\\lib\\site-packages\\IPython\\core\\interactiveshell.py\", line 2067, in showtraceback\n",
      "    value, tb, tb_offset=tb_offset)\n",
      "  File \"D:\\Anaconda\\lib\\site-packages\\IPython\\core\\ultratb.py\", line 1368, in structured_traceback\n",
      "    self, etype, value, tb, tb_offset, number_of_lines_of_context)\n",
      "  File \"D:\\Anaconda\\lib\\site-packages\\IPython\\core\\ultratb.py\", line 1268, in structured_traceback\n",
      "    self, etype, value, tb, tb_offset, number_of_lines_of_context\n",
      "  File \"D:\\Anaconda\\lib\\site-packages\\IPython\\core\\ultratb.py\", line 1125, in structured_traceback\n",
      "    tb_offset)\n",
      "  File \"D:\\Anaconda\\lib\\site-packages\\IPython\\core\\ultratb.py\", line 1082, in format_exception_as_a_whole\n",
      "    last_unique, recursion_repeat = find_recursion(orig_etype, evalue, records)\n",
      "  File \"D:\\Anaconda\\lib\\site-packages\\IPython\\core\\ultratb.py\", line 382, in find_recursion\n",
      "    return len(records), 0\n",
      "TypeError: object of type 'NoneType' has no len()\n",
      "\n",
      "During handling of the above exception, another exception occurred:\n",
      "\n",
      "Traceback (most recent call last):\n",
      "  File \"D:\\Anaconda\\lib\\site-packages\\IPython\\core\\interactiveshell.py\", line 2064, in showtraceback\n",
      "    stb = value._render_traceback_()\n",
      "AttributeError: 'TypeError' object has no attribute '_render_traceback_'\n",
      "\n",
      "During handling of the above exception, another exception occurred:\n",
      "\n",
      "Traceback (most recent call last):\n",
      "  File \"D:\\Anaconda\\lib\\site-packages\\IPython\\core\\interactiveshell.py\", line 2947, in _run_cell\n",
      "    return runner(coro)\n",
      "  File \"D:\\Anaconda\\lib\\site-packages\\IPython\\core\\async_helpers.py\", line 68, in _pseudo_sync_runner\n",
      "    coro.send(None)\n",
      "  File \"D:\\Anaconda\\lib\\site-packages\\IPython\\core\\interactiveshell.py\", line 3173, in run_cell_async\n",
      "    interactivity=interactivity, compiler=compiler, result=result)\n",
      "  File \"D:\\Anaconda\\lib\\site-packages\\IPython\\core\\interactiveshell.py\", line 3383, in run_ast_nodes\n",
      "    self.showtraceback()\n",
      "  File \"D:\\Anaconda\\lib\\site-packages\\IPython\\core\\interactiveshell.py\", line 2067, in showtraceback\n",
      "    value, tb, tb_offset=tb_offset)\n",
      "  File \"D:\\Anaconda\\lib\\site-packages\\IPython\\core\\ultratb.py\", line 1368, in structured_traceback\n",
      "    self, etype, value, tb, tb_offset, number_of_lines_of_context)\n",
      "  File \"D:\\Anaconda\\lib\\site-packages\\IPython\\core\\ultratb.py\", line 1268, in structured_traceback\n",
      "    self, etype, value, tb, tb_offset, number_of_lines_of_context\n",
      "  File \"D:\\Anaconda\\lib\\site-packages\\IPython\\core\\ultratb.py\", line 1143, in structured_traceback\n",
      "    chained_exceptions_tb_offset)\n",
      "  File \"D:\\Anaconda\\lib\\site-packages\\IPython\\core\\ultratb.py\", line 1082, in format_exception_as_a_whole\n",
      "    last_unique, recursion_repeat = find_recursion(orig_etype, evalue, records)\n",
      "  File \"D:\\Anaconda\\lib\\site-packages\\IPython\\core\\ultratb.py\", line 382, in find_recursion\n",
      "    return len(records), 0\n",
      "TypeError: object of type 'NoneType' has no len()\n",
      "\n",
      "During handling of the above exception, another exception occurred:\n",
      "\n",
      "Traceback (most recent call last):\n",
      "  File \"D:\\Anaconda\\lib\\site-packages\\IPython\\core\\interactiveshell.py\", line 2064, in showtraceback\n",
      "    stb = value._render_traceback_()\n",
      "AttributeError: 'TypeError' object has no attribute '_render_traceback_'\n",
      "\n",
      "During handling of the above exception, another exception occurred:\n",
      "\n",
      "Traceback (most recent call last):\n",
      "  File \"D:\\Anaconda\\lib\\site-packages\\IPython\\core\\ultratb.py\", line 1101, in get_records\n",
      "    return _fixed_getinnerframes(etb, number_of_lines_of_context, tb_offset)\n",
      "  File \"D:\\Anaconda\\lib\\site-packages\\IPython\\core\\ultratb.py\", line 248, in wrapped\n",
      "    return f(*args, **kwargs)\n",
      "  File \"D:\\Anaconda\\lib\\site-packages\\IPython\\core\\ultratb.py\", line 281, in _fixed_getinnerframes\n",
      "    records = fix_frame_records_filenames(inspect.getinnerframes(etb, context))\n",
      "  File \"D:\\Anaconda\\lib\\inspect.py\", line 1502, in getinnerframes\n",
      "    frameinfo = (tb.tb_frame,) + getframeinfo(tb, context)\n",
      "  File \"D:\\Anaconda\\lib\\inspect.py\", line 1460, in getframeinfo\n",
      "    filename = getsourcefile(frame) or getfile(frame)\n",
      "  File \"D:\\Anaconda\\lib\\inspect.py\", line 696, in getsourcefile\n",
      "    if getattr(getmodule(object, filename), '__loader__', None) is not None:\n",
      "  File \"D:\\Anaconda\\lib\\inspect.py\", line 733, in getmodule\n",
      "    if ismodule(module) and hasattr(module, '__file__'):\n",
      "  File \"D:\\Anaconda\\lib\\site-packages\\tensorflow\\__init__.py\", line 50, in __getattr__\n",
      "    module = self._load()\n",
      "  File \"D:\\Anaconda\\lib\\site-packages\\tensorflow\\__init__.py\", line 44, in _load\n",
      "    module = _importlib.import_module(self.__name__)\n",
      "  File \"D:\\Anaconda\\lib\\importlib\\__init__.py\", line 127, in import_module\n",
      "    return _bootstrap._gcd_import(name[level:], package, level)\n",
      "  File \"<frozen importlib._bootstrap>\", line 1006, in _gcd_import\n",
      "  File \"<frozen importlib._bootstrap>\", line 983, in _find_and_load\n",
      "  File \"<frozen importlib._bootstrap>\", line 965, in _find_and_load_unlocked\n",
      "ModuleNotFoundError: No module named 'tensorflow_core.estimator'\n"
     ]
    }
   ],
   "source": [
    "basedir = '.\\\\assignment_dataset'\n",
    "images_dir = os.path.join(basedir,'image')\n",
    "labels_filename = 'label2.csv'\n",
    "# print(images_dir)   # .\\assignment_dataset\\image\n",
    "\n",
    "\n",
    "def extract_features_labels():\n",
    "    \"\"\"\n",
    "    This funtion extracts the features for all images in the folder 'dataset/..'.\n",
    "    It also extracts the tumor label for each image.\n",
    "    :return:\n",
    "        pic_features:  an array containing 68 landmark points for each image in which a face was detected\n",
    "        tumor_labels:      an array containing the gender label (male=0 and female=1) for each image in\n",
    "                            which a face was detected\n",
    "    \"\"\"\n",
    "\n",
    "    all_features = []\n",
    "    all_labels = []\n",
    "    \n",
    "    image_paths = [os.path.join(images_dir, l) for l in os.listdir(images_dir)]\n",
    "#     print(image_paths)   # ‘.\\\\assignment_dataset\\\\image\\\\IMAGE_0032.jpg'\n",
    "    labels_file = open(os.path.join(basedir, labels_filename), 'r')\n",
    "\n",
    "    lines_of_label = labels_file.readlines()\n",
    "#     print(lines_of_label)   # 'IMAGE_0000.jpg,meningioma_tumor,,脑膜瘤\\n'\n",
    "\n",
    "    type_labels = {line.split(',')[0] : line.split(',')[1] for line in lines_of_label[1:]}\n",
    "\n",
    "    # convert tumor names to int\n",
    "    for k,v in type_labels.items():\n",
    "        if v == \"meningioma_tumor\\n\":\n",
    "            type_labels[k] = 1\n",
    "        elif v == 'glioma_tumor\\n':\n",
    "            type_labels[k] = 2\n",
    "        elif v == 'pituitary_tumor\\n':\n",
    "            type_labels[k] = 3\n",
    "        elif v == 'no_tumor\\n':\n",
    "            type_labels[k] = 0\n",
    "\n",
    "    \n",
    "    for img in image_paths:\n",
    "        # pic_features\n",
    "        img_read = cv2.imread(img)  # 把图片转化成 numpy.ndarray，shape=(512, 512, 3)\n",
    "        all_features.append(img_read)   # list\n",
    "        \n",
    "        # tumor_labels\n",
    "        file_name= img.split('\\\\')[-1]\n",
    "        all_labels.append(type_labels[file_name])\n",
    "\n",
    "    pic_features = np.array(all_features)\n",
    "    tumor_labels = np.array(all_labels) \n",
    "\n",
    "    return pic_features, tumor_labels\n",
    "\n",
    "def get_data():\n",
    "\n",
    "    X,y = extract_features_labels()   \n",
    "    # X: landmark_features - ndarray, shape = (134, 68, 2)\n",
    "    # y: gender_labels - list, len= 134\n",
    "    \n",
    "    \n",
    "    Y = np.array([y, -(y - 1)]).T   # Y: ndarray, shape = (134, 2)\n",
    "    print(Y.shape)\n",
    "    tr_X = X[:100]\n",
    "    tr_Y = Y[:100]\n",
    "    te_X = X[100:]\n",
    "    te_Y = Y[100:]\n",
    "    \n",
    "    tr_X2 = tr_X.reshape((100, 512*512*3))\n",
    "    tr_Y2 = list(zip(*tr_Y))[0]\n",
    "    te_X2 = te_X.reshape((56, 512*512*3))\n",
    "    te_Y2 = list(zip(*te_Y))[0]\n",
    "    \n",
    "    print()\n",
    "    print(\"tr_X2:\")\n",
    "    print(tr_X2.shape)   # (100, 136)\n",
    "    print(type(tr_X2))   # numpy.ndarray\n",
    "    print()\n",
    "    print(\"tr_Y2:\")\n",
    "    print(tr_Y2)\n",
    "    print(type(tr_Y2))  # tuple\n",
    "    print(len(tr_Y2))    # len=100\n",
    "\n",
    "\n",
    "    return tr_X2, tr_Y2, te_X2, te_Y2\n",
    "\n",
    "\n",
    "def img_SVM(training_images, training_labels, test_images, test_labels):\n",
    "    classifier = svm.SVC(kernel='linear')\n",
    "\n",
    "    classifier.fit(training_images, training_labels)\n",
    "\n",
    "    pred = classifier.predict(test_images)\n",
    "\n",
    "    print(pred)\n",
    "\n",
    "    print(\"Accuracy:\", accuracy_score(test_labels, pred))\n",
    "\n",
    "\n",
    "tr_X, tr_Y, te_X, te_Y= get_data()\n",
    "# pred=img_SVM(tr_X, tr_Y, te_X, te_Y)\n",
    "# 喂给机器的数据： 100个压缩成2维的array，长度为100的包含gender信息的元组，34个x_test，34个y_test            \n",
    "            \n",
    "\n",
    "img_read = cv2.imread('.\\\\assignment_dataset\\\\image\\\\IMAGE_0032.jpg')  # 把图片转化成 numpy.ndarray，shape=(512, 512, 3)\n",
    "# print(type(img_read))\n",
    "# print(img_read.shape)\n",
    "\n",
    "\n",
    "\n",
    "\n",
    "img_keras = image.load_img('.\\\\assignment_dataset\\\\image\\\\IMAGE_0032.jpg',target_size = None)\n",
    "# print(img_keras)\n",
    "\n",
    "img_keras = image.load_img('.\\\\assignment_dataset\\\\image\\\\IMAGE_0032.jpg',target_size = None)\n",
    "# print(img_keras)\n",
    "\n",
    "img_keras = image.img_to_array(img_keras)\n",
    "# print(img_keras[:,1,1])"
   ]
  },
  {
   "cell_type": "code",
   "execution_count": 23,
   "id": "f3f5e294",
   "metadata": {},
   "outputs": [
    {
     "name": "stdout",
     "output_type": "stream",
     "text": [
      "{'sdfhio': 1, 'sdhou': 2, 'sd': 1, 'fg': 2}\n"
     ]
    }
   ],
   "source": [
    "di = {'sdfhio':\"a\", \"sdhou\": \"b\",'sd':\"a\", \"fg\": \"b\"}\n",
    "for k,v in di.items():\n",
    "    if v == \"a\":\n",
    "        di[k] = 1\n",
    "    elif v == 'b':\n",
    "        di[k] = 2\n",
    "print(di)"
   ]
  },
  {
   "cell_type": "code",
   "execution_count": null,
   "id": "1d76aeb3",
   "metadata": {},
   "outputs": [],
   "source": []
  }
 ],
 "metadata": {
  "kernelspec": {
   "display_name": "Python 3 (ipykernel)",
   "language": "python",
   "name": "python3"
  },
  "language_info": {
   "codemirror_mode": {
    "name": "ipython",
    "version": 3
   },
   "file_extension": ".py",
   "mimetype": "text/x-python",
   "name": "python",
   "nbconvert_exporter": "python",
   "pygments_lexer": "ipython3",
   "version": "3.7.6"
  }
 },
 "nbformat": 4,
 "nbformat_minor": 5
}
